{"DataVersion":3465,"size":[13,8,13],"palette":[{"Name":"stellaeomphalos:stone_set_bricks"},{"Name":"stellaeomphalos:dark_stone_set_bricks"},{"Name":"stellaeomphalos:stone_set_pillar"},{"Name":"stellaeomphalos:stone_set_chiseled"},{"Name":"stellaeomphalos:stone_set"},{"Name":"minecraft:air"},{"Name":"stellaeomphalos:astral_crystal"},{"Name":"minecraft:chest"}],"blocks":[{"pos":[0,2,0],"state":0},{"pos":[0,0,0],"state":1},{"pos":[0,2,1],"state":0},{"pos":[0,0,1],"state":1},{"pos":[0,2,2],"state":0},{"pos":[0,0,2],"state":1},{"pos":[0,2,3],"state":0},{"pos":[0,0,3],"state":1},{"pos":[0,2,4],"state":0},{"pos":[0,0,4],"state":1},{"pos":[0,2,5],"state":0},{"pos":[0,0,5],"state":1},{"pos":[0,2,6],"state":0},{"pos":[0,0,6],"state":1},{"pos":[0,2,7],"state":0},{"pos":[0,0,7],"state":1},{"pos":[0,2,8],"state":0},{"pos":[0,0,8],"state":1},{"pos":[0,2,9],"state":0},{"pos":[0,0,9],"state":1},{"pos":[0,2,10],"state":0},{"pos":[0,0,10],"state":1},{"pos":[0,2,11],"state":0},{"pos":[0,0,11],"state":1},{"pos":[0,2,12],"state":0},{"pos":[0,0,12],"state":1},{"pos":[1,2,0],"state":0},{"pos":[1,0,0],"state":1},{"pos":[1,2,1],"state":0},{"pos":[1,0,1],"state":1},{"pos":[1,2,2],"state":0},{"pos":[1,0,2],"state":1},{"pos":[1,2,3],"state":0},{"pos":[1,0,3],"state":1},{"pos":[1,2,4],"state":0},{"pos":[1,0,4],"state":1},{"pos":[1,2,5],"state":0},{"pos":[1,0,5],"state":1},{"pos":[1,2,6],"state":0},{"pos":[1,0,6],"state":1},{"pos":[1,2,7],"state":0},{"pos":[1,0,7],"state":1},{"pos":[1,2,8],"state":0},{"pos":[1,0,8],"state":1},{"pos":[1,2,9],"state":0},{"pos":[1,0,9],"state":1},{"pos":[1,2,10],"state":0},{"pos":[1,0,10],"state":1},{"pos":[1,2,11],"state":0},{"pos":[1,0,11],"state":1},{"pos":[1,2,12],"state":0},{"pos":[1,0,12],"state":1},{"pos":[2,2,0],"state":0},{"pos":[2,0,0],"state":1},{"pos":[2,2,1],"state":0},{"pos":[2,0,1],"state":1},{"pos":[2,2,2],"state":0},{"pos":[2,0,2],"state":1},{"pos":[2,2,3],"state":0},{"pos":[2,0,3],"state":1},{"pos":[2,2,4],"state":0},{"pos":[2,0,4],"state":1},{"pos":[2,2,5],"state":0},{"pos":[2,0,5],"state":1},{"pos":[2,2,6],"state":0},{"pos":[2,0,6],"state":1},{"pos":[2,2,7],"state":0},{"pos":[2,0,7],"state":1},{"pos":[2,2,8],"state":0},{"pos":[2,0,8],"state":1},{"pos":[2,2,9],"state":0},{"pos":[2,0,9],"state":1},{"pos":[2,2,10],"state":0},{"pos":[2,0,10],"state":1},{"pos":[2,2,11],"state":0},{"pos":[2,0,11],"state":1},{"pos":[2,2,12],"state":0},{"pos":[2,0,12],"state":1},{"pos":[3,2,0],"state":0},{"pos":[3,0,0],"state":1},{"pos":[3,2,1],"state":0},{"pos":[3,0,1],"state":1},{"pos":[3,2,2],"state":0},{"pos":[3,0,2],"state":1},{"pos":[3,2,3],"state":0},{"pos":[3,0,3],"state":1},{"pos":[3,2,4],"state":0},{"pos":[3,0,4],"state":1},{"pos":[3,2,5],"state":0},{"pos":[3,0,5],"state":1},{"pos":[3,2,6],"state":0},{"pos":[3,0,6],"state":1},{"pos":[3,2,7],"state":0},{"pos":[3,0,7],"state":1},{"pos":[3,2,8],"state":0},{"pos":[3,0,8],"state":1},{"pos":[3,2,9],"state":0},{"pos":[3,0,9],"state":1},{"pos":[3,2,10],"state":0},{"pos":[3,0,10],"state":1},{"pos":[3,2,11],"state":0},{"pos":[3,0,11],"state":1},{"pos":[3,2,12],"state":0},{"pos":[3,0,12],"state":1},{"pos":[4,2,0],"state":0},{"pos":[4,0,0],"state":1},{"pos":[4,2,1],"state":0},{"pos":[4,0,1],"state":1},{"pos":[4,2,2],"state":0},{"pos":[4,0,2],"state":1},{"pos":[4,2,3],"state":0},{"pos":[4,0,3],"state":1},{"pos":[4,2,4],"state":0},{"pos":[4,0,4],"state":1},{"pos":[4,2,5],"state":0},{"pos":[4,0,5],"state":1},{"pos":[4,2,6],"state":0},{"pos":[4,0,6],"state":1},{"pos":[4,2,7],"state":0},{"pos":[4,0,7],"state":1},{"pos":[4,2,8],"state":0},{"pos":[4,0,8],"state":1},{"pos":[4,2,9],"state":0},{"pos":[4,0,9],"state":1},{"pos":[4,2,10],"state":0},{"pos":[4,0,10],"state":1},{"pos":[4,2,11],"state":0},{"pos":[4,0,11],"state":1},{"pos":[4,2,12],"state":0},{"pos":[4,0,12],"state":1},{"pos":[5,2,0],"state":0},{"pos":[5,0,0],"state":1},{"pos":[5,2,1],"state":0},{"pos":[5,0,1],"state":1},{"pos":[5,2,2],"state":0},{"pos":[5,0,2],"state":1},{"pos":[5,2,3],"state":0},{"pos":[5,0,3],"state":1},{"pos":[5,2,4],"state":0},{"pos":[5,0,4],"state":1},{"pos":[5,2,5],"state":0},{"pos":[5,0,5],"state":1},{"pos":[5,2,6],"state":0},{"pos":[5,0,6],"state":1},{"pos":[5,2,7],"state":0},{"pos":[5,0,7],"state":1},{"pos":[5,2,8],"state":0},{"pos":[5,0,8],"state":1},{"pos":[5,2,9],"state":0},{"pos":[5,0,9],"state":1},{"pos":[5,2,10],"state":0},{"pos":[5,0,10],"state":1},{"pos":[5,2,11],"state":0},{"pos":[5,0,11],"state":1},{"pos":[5,2,12],"state":0},{"pos":[5,0,12],"state":1},{"pos":[6,2,0],"state":0},{"pos":[6,0,0],"state":1},{"pos":[6,2,1],"state":0},{"pos":[6,0,1],"state":1},{"pos":[6,2,2],"state":0},{"pos":[6,0,2],"state":1},{"pos":[6,2,3],"state":0},{"pos":[6,0,3],"state":1},{"pos":[6,2,4],"state":0},{"pos":[6,0,4],"state":1},{"pos":[6,2,5],"state":0},{"pos":[6,0,5],"state":1},{"pos":[6,2,6],"state":0},{"pos":[6,0,6],"state":1},{"pos":[6,2,7],"state":0},{"pos":[6,0,7],"state":1},{"pos":[6,2,8],"state":0},{"pos":[6,0,8],"state":1},{"pos":[6,2,9],"state":0},{"pos":[6,0,9],"state":1},{"pos":[6,2,10],"state":0},{"pos":[6,0,10],"state":1},{"pos":[6,2,11],"state":0},{"pos":[6,0,11],"state":1},{"pos":[6,2,12],"state":0},{"pos":[6,0,12],"state":1},{"pos":[7,2,0],"state":0},{"pos":[7,0,0],"state":1},{"pos":[7,2,1],"state":0},{"pos":[7,0,1],"state":1},{"pos":[7,2,2],"state":0},{"pos":[7,0,2],"state":1},{"pos":[7,2,3],"state":0},{"pos":[7,0,3],"state":1},{"pos":[7,2,4],"state":0},{"pos":[7,0,4],"state":1},{"pos":[7,2,5],"state":0},{"pos":[7,0,5],"state":1},{"pos":[7,2,6],"state":0},{"pos":[7,0,6],"state":1},{"pos":[7,2,7],"state":0},{"pos":[7,0,7],"state":1},{"pos":[7,2,8],"state":0},{"pos":[7,0,8],"state":1},{"pos":[7,2,9],"state":0},{"pos":[7,0,9],"state":1},{"pos":[7,2,10],"state":0},{"pos":[7,0,10],"state":1},{"pos":[7,2,11],"state":0},{"pos":[7,0,11],"state":1},{"pos":[7,2,12],"state":0},{"pos":[7,0,12],"state":1},{"pos":[8,2,0],"state":0},{"pos":[8,0,0],"state":1},{"pos":[8,2,1],"state":0},{"pos":[8,0,1],"state":1},{"pos":[8,2,2],"state":0},{"pos":[8,0,2],"state":1},{"pos":[8,2,3],"state":0},{"pos":[8,0,3],"state":1},{"pos":[8,2,4],"state":0},{"pos":[8,0,4],"state":1},{"pos":[8,2,5],"state":0},{"pos":[8,0,5],"state":1},{"pos":[8,2,6],"state":0},{"pos":[8,0,6],"state":1},{"pos":[8,2,7],"state":0},{"pos":[8,0,7],"state":1},{"pos":[8,2,8],"state":0},{"pos":[8,0,8],"state":1},{"pos":[8,2,9],"state":0},{"pos":[8,0,9],"state":1},{"pos":[8,2,10],"state":0},{"pos":[8,0,10],"state":1},{"pos":[8,2,11],"state":0},{"pos":[8,0,11],"state":1},{"pos":[8,2,12],"state":0},{"pos":[8,0,12],"state":1},{"pos":[9,2,0],"state":0},{"pos":[9,0,0],"state":1},{"pos":[9,2,1],"state":0},{"pos":[9,0,1],"state":1},{"pos":[9,2,2],"state":0},{"pos":[9,0,2],"state":1},{"pos":[9,2,3],"state":0},{"pos":[9,0,3],"state":1},{"pos":[9,2,4],"state":0},{"pos":[9,0,4],"state":1},{"pos":[9,2,5],"state":0},{"pos":[9,0,5],"state":1},{"pos":[9,2,6],"state":0},{"pos":[9,0,6],"state":1},{"pos":[9,2,7],"state":0},{"pos":[9,0,7],"state":1},{"pos":[9,2,8],"state":0},{"pos":[9,0,8],"state":1},{"pos":[9,2,9],"state":0},{"pos":[9,0,9],"state":1},{"pos":[9,2,10],"state":0},{"pos":[9,0,10],"state":1},{"pos":[9,2,11],"state":0},{"pos":[9,0,11],"state":1},{"pos":[9,2,12],"state":0},{"pos":[9,0,12],"state":1},{"pos":[10,2,0],"state":0},{"pos":[10,0,0],"state":1},{"pos":[10,2,1],"state":0},{"pos":[10,0,1],"state":1},{"pos":[10,2,2],"state":0},{"pos":[10,0,2],"state":1},{"pos":[10,2,3],"state":0},{"pos":[10,0,3],"state":1},{"pos":[10,2,4],"state":0},{"pos":[10,0,4],"state":1},{"pos":[10,2,5],"state":0},{"pos":[10,0,5],"state":1},{"pos":[10,2,6],"state":0},{"pos":[10,0,6],"state":1},{"pos":[10,2,7],"state":0},{"pos":[10,0,7],"state":1},{"pos":[10,2,8],"state":0},{"pos":[10,0,8],"state":1},{"pos":[10,2,9],"state":0},{"pos":[10,0,9],"state":1},{"pos":[10,2,10],"state":0},{"pos":[10,0,10],"state":1},{"pos":[10,2,11],"state":0},{"pos":[10,0,11],"state":1},{"pos":[10,2,12],"state":0},{"pos":[10,0,12],"state":1},{"pos":[11,2,0],"state":0},{"pos":[11,0,0],"state":1},{"pos":[11,2,1],"state":0},{"pos":[11,0,1],"state":1},{"pos":[11,2,2],"state":0},{"pos":[11,0,2],"state":1},{"pos":[11,2,3],"state":0},{"pos":[11,0,3],"state":1},{"pos":[11,2,4],"state":0},{"pos":[11,0,4],"state":1},{"pos":[11,2,5],"state":0},{"pos":[11,0,5],"state":1},{"pos":[11,2,6],"state":0},{"pos":[11,0,6],"state":1},{"pos":[11,2,7],"state":0},{"pos":[11,0,7],"state":1},{"pos":[11,2,8],"state":0},{"pos":[11,0,8],"state":1},{"pos":[11,2,9],"state":0},{"pos":[11,0,9],"state":1},{"pos":[11,2,10],"state":0},{"pos":[11,0,10],"state":1},{"pos":[11,2,11],"state":0},{"pos":[11,0,11],"state":1},{"pos":[11,2,12],"state":0},{"pos":[11,0,12],"state":1},{"pos":[12,2,0],"state":0},{"pos":[12,0,0],"state":1},{"pos":[12,2,1],"state":0},{"pos":[12,0,1],"state":1},{"pos":[12,2,2],"state":0},{"pos":[12,0,2],"state":1},{"pos":[12,2,3],"state":0},{"pos":[12,0,3],"state":1},{"pos":[12,2,4],"state":0},{"pos":[12,0,4],"state":1},{"pos":[12,2,5],"state":0},{"pos":[12,0,5],"state":1},{"pos":[12,2,6],"state":0},{"pos":[12,0,6],"state":1},{"pos":[12,2,7],"state":0},{"pos":[12,0,7],"state":1},{"pos":[12,2,8],"state":0},{"pos":[12,0,8],"state":1},{"pos":[12,2,9],"state":0},{"pos":[12,0,9],"state":1},{"pos":[12,2,10],"state":0},{"pos":[12,0,10],"state":1},{"pos":[12,2,11],"state":0},{"pos":[12,0,11],"state":1},{"pos":[12,2,12],"state":0},{"pos":[12,0,12],"state":1},{"pos":[1,3,1],"state":2},{"pos":[1,4,1],"state":2},{"pos":[1,5,1],"state":2},{"pos":[1,6,1],"state":3},{"pos":[1,3,11],"state":2},{"pos":[1,4,11],"state":2},{"pos":[1,5,11],"state":2},{"pos":[1,6,11],"state":3},{"pos":[11,3,1],"state":2},{"pos":[11,4,1],"state":2},{"pos":[11,5,1],"state":2},{"pos":[11,6,1],"state":3},{"pos":[11,3,11],"state":2},{"pos":[11,4,11],"state":2},{"pos":[11,5,11],"state":2},{"pos":[11,6,11],"state":3},{"pos":[0,1,0],"state":4},{"pos":[0,1,1],"state":4},{"pos":[0,1,2],"state":4},{"pos":[0,1,3],"state":4},{"pos":[0,1,4],"state":4},{"pos":[0,1,5],"state":4},{"pos":[0,1,6],"state":4},{"pos":[0,1,7],"state":4},{"pos":[0,1,8],"state":4},{"pos":[0,1,9],"state":4},{"pos":[0,1,10],"state":4},{"pos":[0,1,11],"state":4},{"pos":[0,1,12],"state":4},{"pos":[1,1,0],"state":4},{"pos":[1,1,1],"state":5},{"pos":[1,1,2],"state":5},{"pos":[1,1,3],"state":5},{"pos":[1,1,4],"state":5},{"pos":[1,1,5],"state":5},{"pos":[1,1,6],"state":5},{"pos":[1,1,7],"state":5},{"pos":[1,1,8],"state":5},{"pos":[1,1,9],"state":5},{"pos":[1,1,10],"state":5},{"pos":[1,1,11],"state":5},{"pos":[1,1,12],"state":4},{"pos":[2,1,0],"state":4},{"pos":[2,1,1],"state":5},{"pos":[2,1,2],"state":5},{"pos":[2,1,3],"state":5},{"pos":[2,1,4],"state":5},{"pos":[2,1,5],"state":5},{"pos":[2,1,6],"state":5},{"pos":[2,1,7],"state":5},{"pos":[2,1,8],"state":5},{"pos":[2,1,9],"state":5},{"pos":[2,1,10],"state":5},{"pos":[2,1,11],"state":5},{"pos":[2,1,12],"state":4},{"pos":[3,1,0],"state":4},{"pos":[3,1,1],"state":5},{"pos":[3,1,2],"state":5},{"pos":[3,1,3],"state":5},{"pos":[3,1,4],"state":5},{"pos":[3,1,5],"state":5},{"pos":[3,1,6],"state":5},{"pos":[3,1,7],"state":5},{"pos":[3,1,8],"state":5},{"pos":[3,1,9],"state":5},{"pos":[3,1,10],"state":5},{"pos":[3,1,11],"state":5},{"pos":[3,1,12],"state":4},{"pos":[4,1,0],"state":4},{"pos":[4,1,1],"state":5},{"pos":[4,1,2],"state":5},{"pos":[4,1,3],"state":5},{"pos":[4,1,4],"state":5},{"pos":[4,1,5],"state":5},{"pos":[4,1,6],"state":5},{"pos":[4,1,7],"state":5},{"pos":[4,1,8],"state":5},{"pos":[4,1,9],"state":5},{"pos":[4,1,10],"state":5},{"pos":[4,1,11],"state":5},{"pos":[4,1,12],"state":4},{"pos":[5,1,0],"state":4},{"pos":[5,1,1],"state":5},{"pos":[5,1,2],"state":5},{"pos":[5,1,3],"state":5},{"pos":[5,1,4],"state":5},{"pos":[5,1,5],"state":5},{"pos":[5,1,6],"state":5},{"pos":[5,1,7],"state":5},{"pos":[5,1,8],"state":5},{"pos":[5,1,9],"state":5},{"pos":[5,1,10],"state":5},{"pos":[5,1,11],"state":5},{"pos":[5,1,12],"state":4},{"pos":[6,1,0],"state":4},{"pos":[6,1,1],"state":5},{"pos":[6,1,2],"state":5},{"pos":[6,1,3],"state":5},{"pos":[6,1,4],"state":5},{"pos":[6,1,5],"state":5},{"pos":[6,1,6],"state":5},{"pos":[6,1,7],"state":5},{"pos":[6,1,8],"state":5},{"pos":[6,1,9],"state":5},{"pos":[6,1,10],"state":5},{"pos":[6,1,11],"state":5},{"pos":[6,1,12],"state":4},{"pos":[7,1,0],"state":4},{"pos":[7,1,1],"state":5},{"pos":[7,1,2],"state":5},{"pos":[7,1,3],"state":5},{"pos":[7,1,4],"state":5},{"pos":[7,1,5],"state":5},{"pos":[7,1,6],"state":5},{"pos":[7,1,7],"state":5},{"pos":[7,1,8],"state":5},{"pos":[7,1,9],"state":5},{"pos":[7,1,10],"state":5},{"pos":[7,1,11],"state":5},{"pos":[7,1,12],"state":4},{"pos":[8,1,0],"state":4},{"pos":[8,1,1],"state":5},{"pos":[8,1,2],"state":5},{"pos":[8,1,3],"state":5},{"pos":[8,1,4],"state":5},{"pos":[8,1,5],"state":5},{"pos":[8,1,6],"state":5},{"pos":[8,1,7],"state":5},{"pos":[8,1,8],"state":5},{"pos":[8,1,9],"state":5},{"pos":[8,1,10],"state":5},{"pos":[8,1,11],"state":5},{"pos":[8,1,12],"state":4},{"pos":[9,1,0],"state":4},{"pos":[9,1,1],"state":5},{"pos":[9,1,2],"state":5},{"pos":[9,1,3],"state":5},{"pos":[9,1,4],"state":5},{"pos":[9,1,5],"state":5},{"pos":[9,1,6],"state":5},{"pos":[9,1,7],"state":5},{"pos":[9,1,8],"state":5},{"pos":[9,1,9],"state":5},{"pos":[9,1,10],"state":5},{"pos":[9,1,11],"state":5},{"pos":[9,1,12],"state":4},{"pos":[10,1,0],"state":4},{"pos":[10,1,1],"state":5},{"pos":[10,1,2],"state":5},{"pos":[10,1,3],"state":5},{"pos":[10,1,4],"state":5},{"pos":[10,1,5],"state":5},{"pos":[10,1,6],"state":5},{"pos":[10,1,7],"state":5},{"pos":[10,1,8],"state":5},{"pos":[10,1,9],"state":5},{"pos":[10,1,10],"state":5},{"pos":[10,1,11],"state":5},{"pos":[10,1,12],"state":4},{"pos":[11,1,0],"state":4},{"pos":[11,1,1],"state":5},{"pos":[11,1,2],"state":5},{"pos":[11,1,3],"state":5},{"pos":[11,1,4],"state":5},{"pos":[11,1,5],"state":5},{"pos":[11,1,6],"state":5},{"pos":[11,1,7],"state":5},{"pos":[11,1,8],"state":5},{"pos":[11,1,9],"state":5},{"pos":[11,1,10],"state":5},{"pos":[11,1,11],"state":5},{"pos":[11,1,12],"state":4},{"pos":[12,1,0],"state":4},{"pos":[12,1,1],"state":4},{"pos":[12,1,2],"state":4},{"pos":[12,1,3],"state":4},{"pos":[12,1,4],"state":4},{"pos":[12,1,5],"state":4},{"pos":[12,1,6],"state":4},{"pos":[12,1,7],"state":4},{"pos":[12,1,8],"state":4},{"pos":[12,1,9],"state":4},{"pos":[12,1,10],"state":4},{"pos":[12,1,11],"state":4},{"pos":[12,1,12],"state":4},{"pos":[6,3,6],"state":6},{"pos":[2,3,2],"state":7,"nbt":{"LootTable":"stellaeomphalos:chests/shrine"}},{"pos":[10,3,10],"state":7,"nbt":{"LootTable":"stellaeomphalos:chests/shrine"}}],"entities":[]}