{"DataVersion":3465,"size":[7,6,7],"palette":[{"Name":"stellaeomphalos:stone_set_bricks"},{"Name":"stellaeomphalos:stone_set_pillar"},{"Name":"stellaeomphalos:stone_set_chiseled"},{"Name":"stellaeomphalos:sky_crystal_cluster"},{"Name":"minecraft:chest"}],"blocks":[{"pos":[0,0,0],"state":0},{"pos":[0,0,1],"state":0},{"pos":[0,0,2],"state":0},{"pos":[0,0,3],"state":0},{"pos":[0,0,4],"state":0},{"pos":[0,0,5],"state":0},{"pos":[0,0,6],"state":0},{"pos":[1,0,0],"state":0},{"pos":[1,0,1],"state":0},{"pos":[1,0,2],"state":0},{"pos":[1,0,3],"state":0},{"pos":[1,0,4],"state":0},{"pos":[1,0,5],"state":0},{"pos":[1,0,6],"state":0},{"pos":[2,0,0],"state":0},{"pos":[2,0,1],"state":0},{"pos":[2,0,2],"state":0},{"pos":[2,0,3],"state":0},{"pos":[2,0,4],"state":0},{"pos":[2,0,5],"state":0},{"pos":[2,0,6],"state":0},{"pos":[3,0,0],"state":0},{"pos":[3,0,1],"state":0},{"pos":[3,0,2],"state":0},{"pos":[3,0,3],"state":0},{"pos":[3,0,4],"state":0},{"pos":[3,0,5],"state":0},{"pos":[3,0,6],"state":0},{"pos":[4,0,0],"state":0},{"pos":[4,0,1],"state":0},{"pos":[4,0,2],"state":0},{"pos":[4,0,3],"state":0},{"pos":[4,0,4],"state":0},{"pos":[4,0,5],"state":0},{"pos":[4,0,6],"state":0},{"pos":[5,0,0],"state":0},{"pos":[5,0,1],"state":0},{"pos":[5,0,2],"state":0},{"pos":[5,0,3],"state":0},{"pos":[5,0,4],"state":0},{"pos":[5,0,5],"state":0},{"pos":[5,0,6],"state":0},{"pos":[6,0,0],"state":0},{"pos":[6,0,1],"state":0},{"pos":[6,0,2],"state":0},{"pos":[6,0,3],"state":0},{"pos":[6,0,4],"state":0},{"pos":[6,0,5],"state":0},{"pos":[6,0,6],"state":0},{"pos":[1,1,1],"state":1},{"pos":[1,2,1],"state":1},{"pos":[1,3,1],"state":1},{"pos":[1,4,1],"state":2},{"pos":[1,1,5],"state":1},{"pos":[1,2,5],"state":1},{"pos":[1,3,5],"state":1},{"pos":[1,4,5],"state":2},{"pos":[5,1,1],"state":1},{"pos":[5,2,1],"state":1},{"pos":[5,3,1],"state":1},{"pos":[5,4,1],"state":2},{"pos":[5,1,5],"state":1},{"pos":[5,2,5],"state":1},{"pos":[5,3,5],"state":1},{"pos":[5,4,5],"state":2},{"pos":[3,1,3],"state":3},{"pos":[2,1,2],"state":4,"nbt":{"LootTable":"stellaeomphalos:chests/shrine"}},{"pos":[4,1,4],"state":4,"nbt":{"LootTable":"stellaeomphalos:chests/shrine"}}],"entities":[]}